INFO 04-29 20:23:44 [__init__.py:239] Automatically detected platform cuda.
Process Process-1:
Traceback (most recent call last):
  File "/usr/local/lib/python3.12/dist-packages/huggingface_hub/utils/_http.py", line 409, in hf_raise_for_status
    response.raise_for_status()
  File "/usr/local/lib/python3.12/dist-packages/requests/models.py", line 1024, in raise_for_status
    raise HTTPError(http_error_msg, response=self)
requests.exceptions.HTTPError: 401 Client Error: Unauthorized for url: https://huggingface.co/mistralai/Mistral-7B-Instruct-v0.2/resolve/main/config.json

The above exception was the direct cause of the following exception:

Traceback (most recent call last):
  File "/usr/local/lib/python3.12/dist-packages/transformers/utils/hub.py", line 424, in cached_files
    hf_hub_download(
  File "/usr/local/lib/python3.12/dist-packages/huggingface_hub/utils/_validators.py", line 114, in _inner_fn
    return fn(*args, **kwargs)
           ^^^^^^^^^^^^^^^^^^^
  File "/usr/local/lib/python3.12/dist-packages/huggingface_hub/file_download.py", line 961, in hf_hub_download
    return _hf_hub_download_to_cache_dir(
           ^^^^^^^^^^^^^^^^^^^^^^^^^^^^^^
  File "/usr/local/lib/python3.12/dist-packages/huggingface_hub/file_download.py", line 1068, in _hf_hub_download_to_cache_dir
    _raise_on_head_call_error(head_call_error, force_download, local_files_only)
  File "/usr/local/lib/python3.12/dist-packages/huggingface_hub/file_download.py", line 1596, in _raise_on_head_call_error
    raise head_call_error
  File "/usr/local/lib/python3.12/dist-packages/huggingface_hub/file_download.py", line 1484, in _get_metadata_or_catch_error
    metadata = get_hf_file_metadata(
               ^^^^^^^^^^^^^^^^^^^^^
  File "/usr/local/lib/python3.12/dist-packages/huggingface_hub/utils/_validators.py", line 114, in _inner_fn
    return fn(*args, **kwargs)
           ^^^^^^^^^^^^^^^^^^^
  File "/usr/local/lib/python3.12/dist-packages/huggingface_hub/file_download.py", line 1401, in get_hf_file_metadata
    r = _request_wrapper(
        ^^^^^^^^^^^^^^^^^
  File "/usr/local/lib/python3.12/dist-packages/huggingface_hub/file_download.py", line 285, in _request_wrapper
    response = _request_wrapper(
               ^^^^^^^^^^^^^^^^^
  File "/usr/local/lib/python3.12/dist-packages/huggingface_hub/file_download.py", line 309, in _request_wrapper
    hf_raise_for_status(response)
  File "/usr/local/lib/python3.12/dist-packages/huggingface_hub/utils/_http.py", line 426, in hf_raise_for_status
    raise _format(GatedRepoError, message, response) from e
huggingface_hub.errors.GatedRepoError: 401 Client Error. (Request ID: Root=1-68113530-41b1cbe9558ed397160a6a7a;d42fb3e6-f1b3-4464-a28f-1ce93853b0e4)

Cannot access gated repo for url https://huggingface.co/mistralai/Mistral-7B-Instruct-v0.2/resolve/main/config.json.
Access to model mistralai/Mistral-7B-Instruct-v0.2 is restricted. You must have access to it and be authenticated to access it. Please log in.

The above exception was the direct cause of the following exception:

Traceback (most recent call last):
  File "/usr/lib/python3.12/multiprocessing/process.py", line 314, in _bootstrap
    self.run()
  File "/usr/lib/python3.12/multiprocessing/process.py", line 108, in run
    self._target(*self._args, **self._kwargs)
  File "/root/litang/github/test/vllm/examples/lmcache/disagg_prefill_lmcache_v0.py", line 57, in run_prefill
    llm = LLM(model="mistralai/Mistral-7B-Instruct-v0.2",
          ^^^^^^^^^^^^^^^^^^^^^^^^^^^^^^^^^^^^^^^^^^^^^^^
  File "/root/litang/github/test/vllm/vllm/utils.py", line 1161, in inner
    return fn(*args, **kwargs)
           ^^^^^^^^^^^^^^^^^^^
  File "/root/litang/github/test/vllm/vllm/entrypoints/llm.py", line 247, in __init__
    self.llm_engine = LLMEngine.from_engine_args(
                      ^^^^^^^^^^^^^^^^^^^^^^^^^^^
  File "/root/litang/github/test/vllm/vllm/engine/llm_engine.py", line 503, in from_engine_args
    vllm_config = engine_args.create_engine_config(usage_context)
                  ^^^^^^^^^^^^^^^^^^^^^^^^^^^^^^^^^^^^^^^^^^^^^^^
  File "/root/litang/github/test/vllm/vllm/engine/arg_utils.py", line 1099, in create_engine_config
    model_config = self.create_model_config()
                   ^^^^^^^^^^^^^^^^^^^^^^^^^^
  File "/root/litang/github/test/vllm/vllm/engine/arg_utils.py", line 987, in create_model_config
    return ModelConfig(
           ^^^^^^^^^^^^
  File "/root/litang/github/test/vllm/vllm/config.py", line 451, in __init__
    hf_config = get_config(self.hf_config_path or self.model,
                ^^^^^^^^^^^^^^^^^^^^^^^^^^^^^^^^^^^^^^^^^^^^^
  File "/root/litang/github/test/vllm/vllm/transformers_utils/config.py", line 307, in get_config
    config_dict, _ = PretrainedConfig.get_config_dict(
                     ^^^^^^^^^^^^^^^^^^^^^^^^^^^^^^^^^
  File "/usr/local/lib/python3.12/dist-packages/transformers/configuration_utils.py", line 590, in get_config_dict
    config_dict, kwargs = cls._get_config_dict(pretrained_model_name_or_path, **kwargs)
                          ^^^^^^^^^^^^^^^^^^^^^^^^^^^^^^^^^^^^^^^^^^^^^^^^^^^^^^^^^^^^^
  File "/usr/local/lib/python3.12/dist-packages/transformers/configuration_utils.py", line 649, in _get_config_dict
    resolved_config_file = cached_file(
                           ^^^^^^^^^^^^
  File "/usr/local/lib/python3.12/dist-packages/transformers/utils/hub.py", line 266, in cached_file
    file = cached_files(path_or_repo_id=path_or_repo_id, filenames=[filename], **kwargs)
           ^^^^^^^^^^^^^^^^^^^^^^^^^^^^^^^^^^^^^^^^^^^^^^^^^^^^^^^^^^^^^^^^^^^^^^^^^^^^^
  File "/usr/local/lib/python3.12/dist-packages/transformers/utils/hub.py", line 481, in cached_files
    raise OSError(
OSError: You are trying to access a gated repo.
Make sure to have access to it at https://huggingface.co/mistralai/Mistral-7B-Instruct-v0.2.
401 Client Error. (Request ID: Root=1-68113530-41b1cbe9558ed397160a6a7a;d42fb3e6-f1b3-4464-a28f-1ce93853b0e4)

Cannot access gated repo for url https://huggingface.co/mistralai/Mistral-7B-Instruct-v0.2/resolve/main/config.json.
Access to model mistralai/Mistral-7B-Instruct-v0.2 is restricted. You must have access to it and be authenticated to access it. Please log in.
Process Process-2:
Traceback (most recent call last):
  File "/usr/local/lib/python3.12/dist-packages/huggingface_hub/utils/_http.py", line 409, in hf_raise_for_status
    response.raise_for_status()
  File "/usr/local/lib/python3.12/dist-packages/requests/models.py", line 1024, in raise_for_status
    raise HTTPError(http_error_msg, response=self)
requests.exceptions.HTTPError: 401 Client Error: Unauthorized for url: https://huggingface.co/mistralai/Mistral-7B-Instruct-v0.2/resolve/main/config.json

The above exception was the direct cause of the following exception:

Traceback (most recent call last):
  File "/usr/local/lib/python3.12/dist-packages/transformers/utils/hub.py", line 424, in cached_files
    hf_hub_download(
  File "/usr/local/lib/python3.12/dist-packages/huggingface_hub/utils/_validators.py", line 114, in _inner_fn
    return fn(*args, **kwargs)
           ^^^^^^^^^^^^^^^^^^^
  File "/usr/local/lib/python3.12/dist-packages/huggingface_hub/file_download.py", line 961, in hf_hub_download
    return _hf_hub_download_to_cache_dir(
           ^^^^^^^^^^^^^^^^^^^^^^^^^^^^^^
  File "/usr/local/lib/python3.12/dist-packages/huggingface_hub/file_download.py", line 1068, in _hf_hub_download_to_cache_dir
    _raise_on_head_call_error(head_call_error, force_download, local_files_only)
  File "/usr/local/lib/python3.12/dist-packages/huggingface_hub/file_download.py", line 1596, in _raise_on_head_call_error
    raise head_call_error
  File "/usr/local/lib/python3.12/dist-packages/huggingface_hub/file_download.py", line 1484, in _get_metadata_or_catch_error
    metadata = get_hf_file_metadata(
               ^^^^^^^^^^^^^^^^^^^^^
  File "/usr/local/lib/python3.12/dist-packages/huggingface_hub/utils/_validators.py", line 114, in _inner_fn
    return fn(*args, **kwargs)
           ^^^^^^^^^^^^^^^^^^^
  File "/usr/local/lib/python3.12/dist-packages/huggingface_hub/file_download.py", line 1401, in get_hf_file_metadata
    r = _request_wrapper(
        ^^^^^^^^^^^^^^^^^
  File "/usr/local/lib/python3.12/dist-packages/huggingface_hub/file_download.py", line 285, in _request_wrapper
    response = _request_wrapper(
               ^^^^^^^^^^^^^^^^^
  File "/usr/local/lib/python3.12/dist-packages/huggingface_hub/file_download.py", line 309, in _request_wrapper
    hf_raise_for_status(response)
  File "/usr/local/lib/python3.12/dist-packages/huggingface_hub/utils/_http.py", line 426, in hf_raise_for_status
    raise _format(GatedRepoError, message, response) from e
huggingface_hub.errors.GatedRepoError: 401 Client Error. (Request ID: Root=1-68113530-1ad4a4f2405fca615819e179;0a87edc4-adff-4a80-8b19-02c9b0b07c1d)

Cannot access gated repo for url https://huggingface.co/mistralai/Mistral-7B-Instruct-v0.2/resolve/main/config.json.
Access to model mistralai/Mistral-7B-Instruct-v0.2 is restricted. You must have access to it and be authenticated to access it. Please log in.

The above exception was the direct cause of the following exception:

Traceback (most recent call last):
  File "/usr/lib/python3.12/multiprocessing/process.py", line 314, in _bootstrap
    self.run()
  File "/usr/lib/python3.12/multiprocessing/process.py", line 108, in run
    self._target(*self._args, **self._kwargs)
  File "/root/litang/github/test/vllm/examples/lmcache/disagg_prefill_lmcache_v0.py", line 86, in run_decode
    llm = LLM(model="mistralai/Mistral-7B-Instruct-v0.2",
          ^^^^^^^^^^^^^^^^^^^^^^^^^^^^^^^^^^^^^^^^^^^^^^^
  File "/root/litang/github/test/vllm/vllm/utils.py", line 1161, in inner
    return fn(*args, **kwargs)
           ^^^^^^^^^^^^^^^^^^^
  File "/root/litang/github/test/vllm/vllm/entrypoints/llm.py", line 247, in __init__
    self.llm_engine = LLMEngine.from_engine_args(
                      ^^^^^^^^^^^^^^^^^^^^^^^^^^^
  File "/root/litang/github/test/vllm/vllm/engine/llm_engine.py", line 503, in from_engine_args
    vllm_config = engine_args.create_engine_config(usage_context)
                  ^^^^^^^^^^^^^^^^^^^^^^^^^^^^^^^^^^^^^^^^^^^^^^^
  File "/root/litang/github/test/vllm/vllm/engine/arg_utils.py", line 1099, in create_engine_config
    model_config = self.create_model_config()
                   ^^^^^^^^^^^^^^^^^^^^^^^^^^
  File "/root/litang/github/test/vllm/vllm/engine/arg_utils.py", line 987, in create_model_config
    return ModelConfig(
           ^^^^^^^^^^^^
  File "/root/litang/github/test/vllm/vllm/config.py", line 451, in __init__
    hf_config = get_config(self.hf_config_path or self.model,
                ^^^^^^^^^^^^^^^^^^^^^^^^^^^^^^^^^^^^^^^^^^^^^
  File "/root/litang/github/test/vllm/vllm/transformers_utils/config.py", line 307, in get_config
    config_dict, _ = PretrainedConfig.get_config_dict(
                     ^^^^^^^^^^^^^^^^^^^^^^^^^^^^^^^^^
  File "/usr/local/lib/python3.12/dist-packages/transformers/configuration_utils.py", line 590, in get_config_dict
    config_dict, kwargs = cls._get_config_dict(pretrained_model_name_or_path, **kwargs)
                          ^^^^^^^^^^^^^^^^^^^^^^^^^^^^^^^^^^^^^^^^^^^^^^^^^^^^^^^^^^^^^
  File "/usr/local/lib/python3.12/dist-packages/transformers/configuration_utils.py", line 649, in _get_config_dict
    resolved_config_file = cached_file(
                           ^^^^^^^^^^^^
  File "/usr/local/lib/python3.12/dist-packages/transformers/utils/hub.py", line 266, in cached_file
    file = cached_files(path_or_repo_id=path_or_repo_id, filenames=[filename], **kwargs)
           ^^^^^^^^^^^^^^^^^^^^^^^^^^^^^^^^^^^^^^^^^^^^^^^^^^^^^^^^^^^^^^^^^^^^^^^^^^^^^
  File "/usr/local/lib/python3.12/dist-packages/transformers/utils/hub.py", line 481, in cached_files
    raise OSError(
OSError: You are trying to access a gated repo.
Make sure to have access to it at https://huggingface.co/mistralai/Mistral-7B-Instruct-v0.2.
401 Client Error. (Request ID: Root=1-68113530-1ad4a4f2405fca615819e179;0a87edc4-adff-4a80-8b19-02c9b0b07c1d)

Cannot access gated repo for url https://huggingface.co/mistralai/Mistral-7B-Instruct-v0.2/resolve/main/config.json.
Access to model mistralai/Mistral-7B-Instruct-v0.2 is restricted. You must have access to it and be authenticated to access it. Please log in.
